Workbook

Sheet Costo $ energía
B2: JMAS | C2: Enero | D2: Febrero | E2: Marzo | F2: Abril | G2: Mayo | H2: Junio | I2: Julio | J2: Agosto | K2: Septiembre | L2: Octubre | M2: Noviembre | N2: Diciembre | O2: Para el dato Diciembre | P2: $ MN Energia/ año | Q2: $ MN Energia/día
B3: Juarez | C3: 26489188 | D3: 26969363 | E3: 26352177 | F3: 27363744 | G3: 27621596 | H3: 29255271 | I3: 31537327 | J3: 33000333 | K3: 32742152 | L3: 31609993 | M3: 31763279 | N3: =O3/11 -> 29518584 | O3: =SUM(C3:M3) -> 3.2470442e+08 | P3: =SUM(C3:N3) -> 3.5422301e+08 | Q3: =P3/365 -> 970473.99
B4: Chihuahua | C4: 24809542 | D4: 25615588 | E4: 24230756 | F4: 25717746 | G4: 24958049 | H4: 25477157 | I4: 26513493 | J4: 25772433 | K4: 26127975 | L4: 25905655 | M4: 26792375 | N4: =O4/11 -> 25629161 | O4: =SUM(C4:M4) -> 2.8192077e+08 | P4: =SUM(C4:N4) -> 3.0754993e+08 | Q4: =P4/365 -> 842602.54
B5: Cuauhtemoc | C5: 6551701 | D5: 6051456.2 | E5: 6531215.9 | F5: 6445407.4 | G5: 6742474.3 | H5: 6012978 | I5: 5951805.9 | J5: 5475621.7 | K5: 6437385 | L5: 6282298.3 | M5: 8864585.8 | N5: =O5/11 -> 6486084.5 | O5: =SUM(C5:M5) -> 71346930 | P5: =SUM(C5:N5) -> 77833014 | Q5: =P5/365 -> 213241.13
B6: Parral | C6: 3870367.7 | D6: 4048721.3 | E6: 4279979.9 | F6: 4447310.2 | G6: 4445395.8 | H6: 4628376.5 | I6: 4879527.5 | J6: 4806606.4 | K6: 4502525.8 | L6: 4628870.2 | M6: 4156529.4 | N6: =O6/11 -> 4426746.4 | O6: =SUM(C6:M6) -> 48694211 | P6: =SUM(C6:N6) -> 53120957 | Q6: =P6/365 -> 145536.87
P7: =SUM(P4:P8) -> 4.6868951e+08 | Q7: =SUM(Q4:Q8) -> 1284080.9
B8: Fila PIGo 30 y Cuahtëmoc 31

Sheet Energia kWh de Operacion
B2: JMAS | C2: Enero | D2: Febrero | E2: Marzo | F2: Abril | G2: Mayo | H2: Junio | I2: Julio | J2: Agosto | K2: Septiembre | L2: Octubre | M2: Noviembre | N2: Diciembre | O2: Para el dato Diciembre | P2: kWh/año | Q2: kWh/día
B3: Juarez | C3: 10571388 | D3: 9794125 | E3: 10931212 | F3: 10822283 | G3: 11599977 | H3: 12205384 | I3: 12843614 | J3: 12917630 | K3: 12105818 | L3: 12161097 | M3: 11248300 | N3: =O3/11 -> 11563712 | O3: =SUM(C3:M3) -> 127200828 | P3: =SUM(C3:N3) -> 1.3876454e+08 | Q3: =P3/365 -> 380176.82 | S3: 3.5422301e+08 | T3: =S3/P3 -> 2.5526911 | U3: 2 | V3: =U3/T3 -> 0.78348688 | W3: =1-V3 -> 0.21651312
B4: Chihuahua | C4: 10979385 | D4: 10100773 | E4: 11182999 | F4: 10643383 | G4: 10920416 | H4: 10651681 | I4: 11056431 | J4: 10848896 | K4: 10677179 | L4: 11190006 | M4: 11190006 | N4: =O4/11 -> 10858287 | O4: =SUM(C4:M4) -> 1.1944115e+08 | P4: =SUM(C4:N4) -> 1.3029944e+08 | Q4: =P4/365 -> 356984.77 | S4: 3.0754993e+08 | T4: =S4/P4 -> 2.3603319 | U4: 2 | V4: =U4/T4 -> 0.84733846 | W4: =1-V4 -> 0.15266154
B5: Cuauhtemoc | C5: 2646482 | D5: 2580916 | E5: 2733866 | F5: 2563557 | G5: 2573930 | H5: 2300732 | I5: 2359713 | J5: 2288856 | K5: 2183224 | L5: 2355729 | M5: 2314903 | N5: =O5/11 -> 2445628 | O5: =SUM(C5:M5) -> 26901908 | P5: =SUM(C5:N5) -> 29347536 | Q5: =P5/365 -> 80404.208 | S5: 77833014 | T5: =S5/P5 -> 2.6521141 | U5: 2 | V5: =U5/T5 -> 0.75411537 | W5: =1-V5 -> 0.24588463
B6: Parral | C6: 1629284 | D6: 1573183 | E6: 1752384 | F6: 1694165 | G6: 1774848 | H6: 1629284 | I6: 1814737 | J6: 1826767 | K6: 1699752 | L6: 1828943 | M6: 1572803 | N6: =O6/11 -> 1708740.9 | O6: =SUM(C6:M6) -> 18796150 | P6: =SUM(C6:N6) -> 20504891 | Q6: =P6/365 -> 56177.783 | S6: 53120957 | T6: =S6/P6 -> 2.5906481 | U6: 2 | V6: =U6/T6 -> 0.77200758 | W6: =1-V6 -> 0.22799242
P7: =SUM(P4:P6) -> 1.8015187e+08 | Q7: =SUM(Q4:Q6) -> 493566.76
B8: Fila PIGO 47 y Cuahtémoc 56

Sheet Volumen H2O m3
B2: JMAS | C2: Enero | D2: Febrero | E2: Marzo | F2: Abril | G2: Mayo | H2: Junio | I2: Julio | J2: Agosto | K2: Septiembre | L2: Octubre | M2: Noviembre | N2: Diciembre | O2: Para el dato Diciembre | P2: Agua M3/año | Q2: Agua M3/día
B3: Juarez | C3: 14099329 | D3: 13125177 | E3: 14602325 | F3: 14479094 | G3: 15709949 | H3: 16488057 | I3: 16934659 | J3: 17290828 | K3: 15979449 | L3: 15805658 | M3: 14738845 | N3: =O3/11 -> 15386670 | O3: =SUM(C3:M3) -> 169253370 | P3: =SUM(C3:N3) -> 184640040 | Q3: =P3/365 -> 505863.12
B4: Chihuahua | C4: 11216914 | D4: 10501654 | E4: 11327365 | F4: 10791655 | G4: 11273231 | H4: 10826534 | I4: 11088642 | J4: 11142751 | K4: 10577936 | L4: 11062295 | M4: 10900083 | N4: =O4/11 -> 10973551 | O4: =SUM(C4:M4) -> 120709060 | P4: =SUM(C4:N4) -> 1.3168261e+08 | Q4: =P4/365 -> 360774.28
B5: Cuauhtemoc | C5: 1706171 | D5: 1518447 | E5: 1659043 | F5: 1649909 | G5: 1512798 | H5: 1560572 | I5: 1397519 | J5: 1474041 | K5: 1279227 | L5: 1488197 | M5: 1373808 | N5: =O5/11 -> 1510884.7 | O5: =SUM(C5:M5) -> 16619732 | P5: =SUM(C5:N5) -> 18130617 | Q5: =P5/365 -> 49672.923
B6: Parral | C6: 1026746 | D6: 994090 | E6: 992741 | F6: 944314 | G6: 1035071 | H6: 938109 | I6: 1030266 | J6: 1059418 | K6: 1036564 | L6: 1053621 | M6: 1000496 | N6: =O6/11 -> 1010130.5 | O6: =SUM(C6:M6) -> 11111436 | P6: =SUM(C6:N6) -> 12121567 | Q6: =P6/365 -> 33209.771
P7: =SUM(P4:P6) -> 1.6193479e+08 | Q7: =SUM(Q4:Q6) -> 443656.97
B8: Fila PIGO 57 y Cuahtémoc 69

Sheet Resumen
B2: JMAS | D2: $ MN Energia/ año | E2: $ MN Energia/día | G2: kWh/año | H2: kWh/día | J2: Agua M3/año | K2: Agua M3/día | L2: kWh/dia | M2: 3 hrs almacenamiento | N2: 1 BESS = 5MWh
B3: Juarez | D3: 3.5422301e+08 | E3: 970473.99 | G3: 1.3876454e+08 | H3: 380176.82 | J3: 184640040 | K3: 505863.12 | L3: =G3/365 -> 380176.82 | M3: =(L3/24)*3 -> 47522.103 | N3: =M3/5000 -> 9.5044205
B4: Chihuahua | D4: 3.0754993e+08 | E4: 842602.54 | G4: 1.3029944e+08 | H4: 356984.77 | J4: 1.3168261e+08 | K4: 360774.28 | L4: =G4/365 -> 356984.77 | M4: =(L4/24)*3 -> 44623.096 | N4: =M4/5000 -> 8.9246193
B5: Cuauhtemoc | D5: 77833014 | E5: 213241.13 | G5: 29347536 | H5: 80404.208 | J5: 18130617 | K5: 49672.923 | L5: =G5/365 -> 80404.208 | M5: =(L5/24)*3 -> 10050.526 | N5: =M5/5000 -> 2.0101052
B6: Parral | D6: 53120957 | E6: 145536.87 | G6: 20504891 | H6: 56177.783 | J6: 12121567 | K6: 33209.771 | L6: =G6/365 -> 56177.783 | M6: =(L6/24)*3 -> 7022.2229 | N6: =M6/5000 -> 1.4044446
D7: =SUM(D3:D6) -> 7.9272691e+08 | E7: =SUM(E3:E6) -> 2171854.5 | G7: =SUM(G3:G6) -> 3.1891641e+08 | H7: =SUM(H3:H6) -> 873743.58 | J7: =SUM(J3:J6) -> 3.4657483e+08 | K7: =SUM(K3:K6) -> 949520.09 | L7: =SUM(L3:L6) -> 873743.58 | M7: =(L7/24)*3 -> 109217.95 | N7: =M7/5000 -> 21.84359
R8: =40000*P18 -> 6009753.5 | S8: =N18*S9 -> 25541452 | T8: Margen Obra
P9: Costo | Q9: 0.65 | R9: usd/Wp | S9: =Q10-Q9 -> 0.17
N10: 1400 | O10: paneles | P10: Venta | Q10: 0.82 | R10: usd/Wp | U10: 40 ft
M11: KWh/año (AC) | N11: 715 | O11: Watts pico | T11: 5000 | U11: kW/h
L12: Helioscope | M12: ='Produccion energía eléctrica'!G21 -> 2124781.5 | N12: =N10*N11 -> 1001000 | O12: Wp | P12: =N12/1000000 -> 1.001 | Q12: MWp | R12: $USD | S12: Baterias kW | T12: # TU 40´
L14: Juarez | M14: ='Energia kWh de Operacion'!P3 -> 1.3876454e+08 | N14: =(M14*$N$12)/$M$12 -> 65372983 | O14: Wp | P14: =N14/1000000 -> 65.372983 | Q14: MWp | R14: =$Q$10*N14 -> 53605846 | S14: =(M22/24)*3 -> 47522.103 | T14: =S14/$T$11 -> 9.5044205
L15: Chihuahua | M15: ='Energia kWh de Operacion'!P4 -> 1.3029944e+08 | N15: =(M15*$N$12)/$M$12 -> 61385013 | O15: Wp | P15: =N15/1000000 -> 61.385013 | Q15: MWp | R15: =$Q$10*N15 -> 50335711 | S15: =(M23/24)*3 -> 44623.096 | T15: =S15/$T$11 -> 8.9246193
L16: Cuauhtemoc | M16: ='Energia kWh de Operacion'!P5 -> 29347536 | N16: =(M16*$N$12)/$M$12 -> 13825837 | O16: Wp | P16: =N16/1000000 -> 13.825837 | Q16: MWp | R16: =$Q$10*N16 -> 11337187 | S16: =(M24/24)*3 -> 10050.526 | T16: =S16/$T$11 -> 2.0101052
L17: Parral | M17: ='Energia kWh de Operacion'!P6 -> 20504891 | N17: =(M17*$N$12)/$M$12 -> 9660003.1 | O17: Wp | P17: =N17/1000000 -> 9.6600031 | Q17: MWp | R17: =$Q$10*N17 -> 7921202.5 | S17: =(M25/24)*3 -> 7022.2229 | T17: =S17/$T$11 -> 1.4044446
M18: =SUM(M14:M17) -> 3.1891641e+08 | N18: =SUM(N14:N17) -> 1.5024384e+08 | O18: Wp | P18: =SUM(P14:P17) -> 150.24384 | Q18: MWp | R18: =SUM(R14:R17) -> 1.2319995e+08
L20: BESS | M20: 1 contenedor 40ft | N20: 5000 | O20: kWh
L21: Ciudad | M21: kWh/dia | N21: kWh | O21: 3 hrs operación | P21: 1 BESS =5,000 kWh/ contenedores | Q21: $850,000 x Contenedor
L22: Juarez | M22: =M14/365 -> 380176.82 | N22: =M22/24 -> 15840.701 | O22: =N22*3 -> 47522.103 | P22: =O22/$N$20 -> 9.5044205 | Q22: =P22*850000 -> 8078757.4
L23: Chihuahua | M23: =M15/365 -> 356984.77 | N23: =M23/24 -> 14874.365 | O23: =N23*3 -> 44623.096 | P23: =O23/$N$20 -> 8.9246193 | Q23: =P23*850000 -> 7585926.4
L24: Cuauhtemoc | M24: =M16/365 -> 80404.208 | N24: =M24/24 -> 3350.1753 | O24: =N24*3 -> 10050.526 | P24: =O24/$N$20 -> 2.0101052 | Q24: =P24*850000 -> 1708589.4
L25: Parral | M25: =M17/365 -> 56177.783 | N25: =M25/24 -> 2340.741 | O25: =N25*3 -> 7022.2229 | P25: =O25/$N$20 -> 1.4044446 | Q25: =P25*850000 -> 1193777.9
Q26: =SUM(Q22:Q25) -> 18567051
L27: 1400 | M27: No. Paneles
L28: 715 | M28: Wp
L29: =L27*L28 -> 1001000 | M29: Cap Instalada (Wp
L30: 10484.3 | M30: m2
O32: No. Paneles (Wp) | P32: =L27 -> 1400 | Q32: área (m2) | R32: área + caminos (m2) | S32: área en hectareas
L33: PV Farm | M33: capacidad MWp | N33: Capacidad (Wp) | O33: 715 | P33: =L29 -> 1001000 | Q33: =L30 -> 10484.3 | R33: =Q33*1.12 -> 11742.416 | S33: =R33/10000 -> 1.1742416
L34: Juarez | M34: =N34/1000000 -> 65.372983 | N34: =N14 -> 65372983 | O34: =N34/$L$28 -> 91430.745 | P34: =O34/$L$27 -> 65.307675 | Q34: =P34*$L$30 -> 684705.26 | R34: =Q34*1.12 -> 766869.89 | S34: =R34/10000 -> 76.686989
L35: Chihuahua | M35: =N35/1000000 -> 61.385013 | N35: =N15 -> 61385013 | O35: =N35/$L$28 -> 85853.166 | P35: =O35/$L$27 -> 61.32369 | Q35: =P35*$L$30 -> 642935.96 | R35: =Q35*1.12 -> 720088.28 | S35: =R35/10000 -> 72.008828
L36: Cuauhtemoc | M36: =N36/1000000 -> 13.825837 | N36: =N16 -> 13825837 | O36: =N36/$L$28 -> 19336.836 | P36: =O36/$L$27 -> 13.812025 | Q36: =P36*$L$30 -> 144809.42 | R36: =Q36*1.12 -> 162186.55 | S36: =R36/10000 -> 16.218655
L37: Parral | M37: =N37/1000000 -> 9.6600031 | N37: =N17 -> 9660003.1 | O37: =N37/$L$28 -> 13510.494 | P37: =O37/$L$27 -> 9.6503527 | Q37: =P37*$L$30 -> 101177.19 | R37: =Q37*1.12 -> 113318.46 | S37: =R37/10000 -> 11.331846
O38: =SUM(O34:O37) -> 210131.24 | P38: =O38/$L$27 -> 150.09374 | Q38: =P38*$L$30 -> 1573627.8 | R38: =Q38*1.12 -> 1762463.2 | S38: =R38/10000 -> 176.24632
L40: EPC | N40: EPC | O40: China Energy, ENEL, Acciona
L41: =R18+Q26 -> 1.41767e+08 | N41: OPEX | O41: Solarig, Acciona, Iberdrola | Q41: 0.025 | R41: del CAPEX
L42: Desarrollo $40,000 | Q42: =L45*0.025 -> 3694418.8
L43: =P18*40000 -> 6009753.5
L44: CAPEX | O44: 2 | P44: kWh | Q44: para la tarifa de arranque simulado
L45: =L41+L43 -> 1.4777675e+08
...

Sheet Produccion energía eléctrica
B4: 715 | C4: Wp
B5: 1400 | C5: No. Paneles
B6: =B4*B5 -> 1001000 | C6: Wp
B8: Month | C8: GHI (kWh/m2) | D8: POA (kWh/m2) | E8: Shaded (kWh/m2) | F8: Nameplate (kWh) | G8: Grid (kWh)
B9: January | C9: 123.2 | D9: 185.5 | E9: 182.4 | F9: 176973.2 | G9: 161209.4
B10: February | C10: 144.1 | D10: 195.7 | E10: 193.7 | F10: 188079 | G10: 167644
B11: March | C11: 196.9 | D11: 232.1 | E11: 230.5 | F11: 224837 | G11: 197211.4
B12: April | C12: 227.7 | D12: 236.1 | E12: 234.5 | F12: 229945.8 | G12: 200627.1
B13: May | C13: 253.8 | D13: 237.4 | E13: 235.7 | F13: 232868.7 | G13: 202062.4
B14: June | C14: 233.7 | D14: 209.9 | E14: 208.2 | F14: 206648.7 | G14: 177384.6
B15: July | C15: 220.3 | D15: 204.4 | E15: 202.1 | F15: 200291.5 | G15: 173850.9
B16: August | C16: 201.6 | D16: 202 | E16: 200.1 | F16: 197314.6 | G16: 171098.7
B17: September | C17: 183.4 | D17: 205.8 | E17: 204.3 | F17: 199646.7 | G17: 172701.4
B18: October | C18: 160.3 | D18: 205.4 | E18: 204.1 | F18: 198685 | G18: 175066.1
B19: November | C19: 134.9 | D19: 200.5 | E19: 197 | F19: 191066.2 | G19: 171341.4
B20: December | C20: 113.6 | D20: 179.3 | E20: 174.8 | F20: 169340.8 | G20: 154584.1
G21: =SUM(G9:G20) -> 2124781.5 | H21: KWh/ año

Sheet Model $
C2: Premisas
C3: Capex | D3: =Resumen!L45 -> 1.4777675e+08
C4: Capital 30% | D4: =D3*0.3 -> 44333025
C5: Deuda 70% | D5: =D3*0.7 -> 1.0344373e+08
C6: TIIE | D6: 0.073646
C7: Spread | D7: =D8-D6 -> 0.036354
C8: Taza | D8: 0.11
C9: Tipo de cambio | D9: 17.7
C10: Amortización años | D10: 15
C11: Arranque tarifa kWh | D11: =2/D9 -> 0.11299435
C12: Incremento anual CFE | D12: 0.06
E13: Año 1 | F13: Año 2 | G13: Año 3 | H13: Año 4 | I13: Año 5 | J13: Año 6 | K13: Año 7 | L13: Año 8 | M13: Año 9 | N13: Año 10 | O13: Año 11 | P13: Año 12 | Q13: Año 13 | R13: Año 14 | S13: Año 15
D14: Ingresos | E14: =Resumen!M18*'Model $'!D11 -> 36035752 | F14: =E14*1.03 -> 37116825 | G14: =F14*1.03 -> 38230330 | H14: =G14*1.03 -> 39377240 | I14: =H14*1.03 -> 40558557 | J14: =I14*1.03 -> 41775313 | K14: =J14*1.03 -> 43028573 | L14: =K14*1.03 -> 44319430 | M14: =L14*1.03 -> 45649013 | ... S14: =R14*1.03 -> 54507309
D16: Intereses | E16: =D5*D8 -> 11378810 | F16: =($D$5-E18)*D8 -> 10620222 | G16: =($D$5-F18)*$D$8 -> 9861635.2 | H16: =($D$5-G18)*$D$8 -> 9103047.8 | I16: =($D$5-H18)*$D$8 -> 8344460.5 | J16: =($D$5-I18)*$D$8 -> 7585873.2 | K16: =($D$5-J18)*$D$8 -> 6827285.9 | L16: =($D$5-K18)*$D$8 -> 6068698.6 | M16: =($D$5-L18)*$D$8 -> 5310111.2 | N16: =($D$5-M18)*$D$8 -> 4551523.9 | ... S16: =($D$5-R18)*$D$8 -> 758587.32
D17: Capital | E17: =D5/15 -> 6896248.4 | F17: =E17 -> 6896248.4 | G17: =F17 -> 6896248.4 | H17: =G17 -> 6896248.4 | I17: =H17 -> 6896248.4 | J17: =I17 -> 6896248.4 | K17: =J17 -> 6896248.4 | L17: =K17 -> 6896248.4 | M17: =L17 -> 6896248.4 | ... S17: =R17 -> 6896248.4
E18: =E17 -> 6896248.4 | F18: =E17+F17 -> 13792497 | G18: =G17+F18 -> 20688745 | H18: =H17+G18 -> 27584993 | I18: =I17+H18 -> 34481242 | J18: =J17+I18 -> 41377490 | K18: =K17+J18 -> 48273739 | L18: =L17+K18 -> 55169987 | M18: =M17+L18 -> 62066235 | N18: =N17+M18 -> 68962484 | ... S18: =S17+R18 -> 1.0344373e+08
D20: Opex | E20: =D3*0.025 -> 3694418.8 | F20: =E20*1.03 -> 3805251.3 | G20: =F20*1.03 -> 3919408.9 | H20: =G20*1.03 -> 4036991.1 | I20: =H20*1.03 -> 4158100.9 | J20: =I20*1.03 -> 4282843.9 | K20: =J20*1.03 -> 4411329.2 | L20: =K20*1.03 -> 4543669.1 | M20: =L20*1.03 -> 4679979.2 | ... S20: =R20*1.03 -> 5588139.9
D22: Egresos | E22: =E16+E17+E20 -> 21969477 | F22: =F16+F17+F20 -> 21321722 | G22: =G16+G17+G20 -> 20677292 | H22: =H16+H17+H20 -> 20036287 | I22: =I16+I17+I20 -> 19398810 | J22: =J16+J17+J20 -> 18764965 | K22: =K16+K17+K20 -> 18134863 | L22: =L16+L17+L20 -> 17508616 | ... S22: =S16+S17+S20 -> 13242976
D24: Margen antes de impuestos | E24: =E14-E22 -> 14066275 | F24: =F14-F22 -> 15795103 | G24: =G14-G22 -> 17553037 | H24: =H14-H22 -> 19340952 | I24: =I14-I22 -> 21159747 | J24: =J14-J22 -> 23010348 | K24: =K14-K22 -> 24893709 | L24: =L14-L22 -> 26810814 | ... S24: =S14-S22 -> 41264333
D25: Acumulado | F25: =E24+F24 -> 29861378 | G25: =G24+F25 -> 47414415 | H25: =H24+G25 -> 66755368 | I25: =I24+H25 -> 87915115 | J25: =J24+I25 -> 1.1092546e+08 | K25: =K24+J25 -> 1.3581917e+08 | L25: =L24+K25 -> 1.6262999e+08 | M25: =M24+L25 -> 1.9139266e+08 | N25: =N24+M25 -> 2.2214299e+08 | ... S25: =S24+R25 -> 4.0703947e+08
D27: Amotización | E27: =D3/5 -> 29555350 | F27: =E27 -> 29555350 | G27: =F27 -> 29555350 | H27: =G27 -> 29555350 | I27: =H27 -> 29555350
D28: ISR | E28: =-E27 -> -29555350 | F28: =-F27 -> -29555350 | G28: =-G27 -> -29555350 | H28: =-H27 -> -29555350 | I28: =-I27 -> -29555350 | J28: =J24*0.35 -> 8053621.8 | K28: =K24*0.35 -> 8712798.3 | L28: =L24*0.35 -> 9383784.9 | M28: =M24*0.35 -> 10066936 | N28: =N24*0.35 -> 10762616 | O28: =O24*0.35 -> 11471202 | P28: =P24*0.35 -> 12193080 | Q28: =Q24*0.35 -> 12928649 | ... S28: =S24*0.35 -> 14442517
D30: Utilidad | E30: =E24-E28 -> 43621626 | F30: =F24-F28 -> 45350453 | G30: =G24-G28 -> 47108387 | H30: =H24-H28 -> 48896302 | I30: =I24-I28 -> 50715097 | J30: =J24-J28 -> 14956726 | K30: =K24-K28 -> 16180911 | L30: =L24-L28 -> 17427029 | ... S30: =S24-S28 -> 26821817
D31: Utilidad acumulada | F31: =E30+F30 -> 88972078 | G31: =G30+F31 -> 1.3608047e+08 | H31: =H30+G31 -> 1.8497677e+08 | I31: =I30+H31 -> 2.3569187e+08 | J31: =J30+I31 -> 2.5064859e+08 | K31: =K30+J31 -> 2.668295e+08 | L31: =L30+K31 -> 2.8425653e+08 | M31: =M30+L31 -> 3.0295227e+08 | N31: =N30+M31 -> 3.2293999e+08 | ... S31: =S30+R31 -> 4.431227e+08
D33: Utilidad del capital en % | E33: =E30/D4 -> 0.98395328 | F33: =F30/$D$4 -> 1.0229497 | G33: =G30/$D$4 -> 1.0626026 | H33: =H30/$D$4 -> 1.1029318 | I33: =I30/$D$4 -> 1.1439575 | J33: =J30/$D$4 -> 0.33737211 | K33: =K30/$D$4 -> 0.36498549 | L33: =L30/$D$4 -> 0.39309361 | M33: =M30/$D$4 -> 0.42171131 | ... S33: =S30/$D$4 -> 0.60500759
D34: Utilidad del proyecto en % | E34: =E30/$D$3 -> 0.29518598 | F34: =F30/$D$3 -> 0.3068849 | G34: =G30/$D$3 -> 0.31878078 | H34: =H30/$D$3 -> 0.33087953 | I34: =I30/$D$3 -> 0.34318725 | J34: =J30/$D$3 -> 0.10121163 | K34: =K30/$D$3 -> 0.10949565 | L34: =L30/$D$3 -> 0.11792808 | ... S34: =S30/$D$3 -> 0.18150228
